<mujoco>
    <compiler angle="degree"/>
    <asset>
        <texture type="skybox" builtin="gradient" rgb1="0.7 0.85 1" rgb2="0.2 0.4 0.8" width="256" height="256"/>
        <texture name="texplane" type="2d" builtin="checker" rgb1="0.4 0.4 0.4" rgb2="0.2 0.2 0.2" width="256"
                 height="256"
                 mark="cross" markrgb="0.8 0.8 0.8"/>
        <material name="matplane" reflectance="0" texture="texplane" texrepeat="20 20" texuniform="true"/>
        <mesh name="platform" vertex="-6 0 0  6 0 0  1.5 18 0  -1.5 18 0  -6 0 1  6 0 1  1.5 18 1  -1.5 18 1"
              scale="0.01 0.01 0.02"/>

        {%- if add_obj_wall -%}
        <mesh name="cube" vertex="0 0 0  1 0 0  1 1 0  0 1 0  0 0 1  1 0 1  1 1 1  0 1 1" scale="0.3 0.01 0.1"/>
        {%- endif -%}
        
        {%- if add_obj_complex -%}
        <mesh name="object_complex_f1" file="assets/object_complex_f1.stl" scale="0.001 0.001 0.001"/>
        <mesh name="object_complex_f2" file="assets/object_complex_f2.stl" scale="0.001 0.001 0.001"/>
        {%- endif -%}
        
        {%- if add_obj_tunnel -%}
        <model name="walls" file="assets/local/walls.xml"/>
        {%- endif -%}
        
        {%- if custom_assets -%}
        {{ custom_assets }}
        {%- endif -%}
    </asset>

    <extension>
        <plugin plugin="mujoco.elasticity.cable"/>
    </extension>

    <!-- Visual settings for rendering -->
    <visual>
        <global offheight="2160" offwidth="3840"/> <!-- Offscreen render resolution -->
        <quality offsamples="8"/>                  <!-- Anti-aliasing sample count -->
    </visual>

    <!-- Global simulation options -->
    <option gravity="0 0 0" integrator="implicitfast"/>

    <!-- World definition -->
    <worldbody>
        <!-- Light source: positioned above, shining downward -->
        <light ambient=".8 .8 .8" pos="0 0 10" dir="0 0 -1" castshadow="false"/>
        <!-- Visible ground plane -->
        <geom type="plane" size="0 0 0.03" material="matplane" rgba="1 1 1 1" contype="0" conaffinity="0"/>
        <!-- Meshes to swipe the whisker against -->
        <body name="test_body">
            <camera name="test_body_cam" pos="0 0 1" orthographic="true" fovy="3"/>
            
            {%- if add_obj_complex -%}
            <geom type="mesh" mesh="object_complex_f1" pos="0.1 0.3 -0.125" euler="0 0 90" rgba="0.5 0.2 0.1 1"/>
            <geom type="mesh" mesh="object_complex_f2" pos="0.1 0.3 -0.125" euler="0 0 90" rgba="0.5 0.2 0.1 1"/>
            {%- endif -%}
            
            {%- if add_obj_boxes -%}
            <geom type="box" size="0.2 0.2 0.03" pos="0.32 -0.2 0.05" euler="0 0 -10" rgba="0.2 0.5 0.1 1"/>
            <geom type="box" size="0.2 0.2 0.03" pos="-0.42 0.2 0.05" euler="0 0 -10" rgba="0.2 0.5 0.1 1"/>
            {%- endif -%}
            
            {%- if add_obj_wall -%}
            <geom type="mesh" mesh="cube" pos="0.15 0.2 0" euler="0 0 100" rgba="0.2 0.5 0.1 1"/>
            {%- endif -%}
            
            {%- if add_obj_tunnel -%}
            <body pos="-0.5 1 0" euler="0 0 -90">
                <attach model="walls" body="wall1" prefix="wall1_"/>
                <attach model="walls" body="wall2" prefix="wall2_"/>
            </body>
            {%- endif -%}
            
            {%- if custom_objects -%}
            {{ custom_objects }}
            {%- endif -%}
        </body>
        
        <!-- Whisker assembly: base with attached moving parts -->
        {%- if use_platform -%}
        <body name="platform" pos="0 0 0.05">
            <geom type="mesh" mesh="platform" rgba=".4 .8 .6 0.5" mass="0.5"/>

            <!-- Slide joints for x and y movement -->
            <!-- Make sure the joint are positioned at the COM, so the coordinates mae sense -->
            <!-- To get the COM print the model data (in simulation) and look at the body_ipos variable of the body -->
            <joint name="body_x_w" type="slide" pos="0 0.072 0" axis="1 0 0" armature="0.1"/>
            <joint name="body_y_w" type="slide" pos="0 0.072 0" axis="0 1 0" armature="0.1" ref="0.072"/>
            <joint name="body_z_w" type="slide" pos="0 0.072 0" axis="0 0 1" armature="0.1" ref="0.06"/>
            <!-- Hinge joint for rotation -->
            <joint name="body_yaw_w" type="hinge" pos="0 0.072 0" axis="0 0 1" armature="0.01" ref="90"/>

            <camera name="platform_cam" pos="0 0.072 0.75"/>

            <!-- Whisker attached to the base -->
            <body name="wsk_r0" pos="0.030 0.125 0.01" axisangle="0 0 1 -15">
                <!-- Hinge joint connecting base to whisker body -->
                <joint name="wsk_r0_defl" type="hinge" axis="0 0 -1" damping="0.01" stiffness="1" armature="0.00001"/>
                <!-- Thin cylinder geom for the whisker body -->
                <geom type="cylinder" size="0.000125 0.01" axisangle="0 1 0 90" rgba=".8 .3 .7 1" mass="0.005"
                      contype="0" conaffinity="0"/>
                <!-- Flexible cable representing the whisker -->
                <composite prefix="wsk_r0_cable" type="cable" curve="s 0 0" count="40 1 1" size="0.1 0 0"
                           initial="none">
                    <plugin plugin="mujoco.elasticity.cable">
                        <config key="twist" value="40e9"/>
                        <config key="bend" value="100e9"/>
                        <config key="vmax" value="0.001"/>
                    </plugin>
                    <!-- Main joint for the cable composite -->
                    <joint kind="main" damping="0.0001" armature="0.00001"/>
                    <!-- Capsule geom for the cable element -->
                    <geom type="capsule" size=".000125" rgba=".8 0 0 1" condim="1" density="6450"/>
                </composite>
            </body>

            <body name="wsk_l0" pos="-0.030 0.125 0.01" axisangle="0 0 1 195">
                <!-- Hinge joint connecting base to whisker body -->
                <joint name="wsk_l0_defl" type="hinge" axis="0 0 1" damping="0.01" stiffness="1" armature="0.00001"/>
                <!-- Thin cylinder geom for the whisker body -->
                <geom type="cylinder" size="0.000125 0.01" axisangle="0 1 0 90" rgba=".8 .3 .7 1" mass="0.005"
                      contype="0" conaffinity="0"/>
                <!-- Flexible cable representing the whisker -->
                <composite prefix="wsk_l0_cable" type="cable" curve="s 0 0" count="40 1 1" size="0.1 0 0"
                           initial="none">
                    <plugin plugin="mujoco.elasticity.cable">
                        <config key="twist" value="40e9"/>
                        <config key="bend" value="100e9"/>
                        <config key="vmax" value="0.001"/>
                    </plugin>
                    <!-- Main joint for the cable composite -->
                    <joint kind="main" damping="0.0001" armature="0.00001"/>
                    <!-- Capsule geom for the cable element -->
                    <geom type="capsule" size=".000125" rgba=".8 0 0 1" condim="1" density="6450"/>
                </composite>
            </body>
        </body>
        {%- endif -%}
    </worldbody>

    {%- if use_platform -%}
    <!-- Actuators: define how joints are controlled -->
    <actuator>
        <velocity joint="body_x_w" name="body_vx"/>
        <velocity joint="body_y_w" name="body_vy"/>
        <velocity joint="body_yaw_w" name="body_omega"/>
    </actuator>

    <!-- Sensors: collect simulation data -->
    <sensor>
        <!-- Whisker base sensors -->
        <jointpos joint="body_x_w" name="body_x_w"/>
        <jointpos joint="body_y_w" name="body_y_w"/>
        <jointpos joint="body_z_w" name="body_z_w"/>
        <jointpos joint="body_yaw_w" name="body_yaw_w"/>

        <!-- Whisker deflection sensor -->
        <jointpos joint="wsk_r0_defl" name="wsk_r0_defl"/>
        <jointpos joint="wsk_l0_defl" name="wsk_l0_defl"/>
    </sensor>
    {%- endif -%}

</mujoco>
