<mujoco>
    <compiler angle="degree"/>
    <asset>
        <texture type="skybox" builtin="gradient" rgb1="1 1 1" rgb2=".6 .8 1" width="256" height="256"/>
        <texture name="texplane" type="2d" builtin="checker" rgb1=".2 .3 .4" rgb2=".1 0.15 0.2" width="512" height="512"
                 mark="cross" markrgb=".8 .8 .8"/>
        <material name="matplane" reflectance="1" texture="texplane" texrepeat="2 2" texuniform="true"/>
    </asset>

    <extension>
        <plugin plugin="mujoco.elasticity.cable"/>
    </extension>

    <!-- Visual settings for rendering -->
    <visual>
        <global offheight="2160" offwidth="3840"/> <!-- Offscreen render resolution -->
        <quality offsamples="8"/>                  <!-- Anti-aliasing sample count -->
    </visual>


    <!-- Global simulation options -->
    <option gravity="0 0 0" integrator="implicitfast"/>

    <!-- Assets: external mesh files -->
    <asset>
        <mesh name="object_complex_f1" file="../assets/object_complex_f1.stl" scale="0.001 0.001 0.001"/>
        <mesh name="object_complex_f2" file="../assets/object_complex_f2.stl" scale="0.001 0.001 0.001"/>
    </asset>

    <!-- World definition -->
    <worldbody>
        <!-- Light source: positioned above, shining downward -->
        <light diffuse=".8 .8 .8" pos="0 0 5" dir="0 0 -1"/>
        <!-- Visible ground plane -->
        <geom type="plane" size="0 0 0.03" material="matplane" rgba="1 1 1 1"/>

        <!-- Additional cameras for alternative viewpoints -->
        <camera name="whisker_cam_3" pos="0.5 -0.1 1.1"/>
        <camera name="whisker_cam_4" pos="-0.1 0.2 0.3" xyaxes="1 0 1 1 1 0"/>

        <!-- Meshes to swipe the whisker against -->
        <body>
            <geom type="mesh" mesh="object_complex_f1" pos="0.8 -0.19 -0.175" euler="0 0 180" rgba="0.5 0.2 0.1 .9"/>
            <geom type="mesh" mesh="object_complex_f2" pos="0.8 -0.19 -0.175" euler="0 0 180" rgba="0.5 0.2 0.1 .9"/>
<!--            <geom type="box" size="0.3 0.3 0.05" pos="0.3 -0.24 0.05" euler="0 0 10" rgba="0.2 0.5 0.1 .9"/>-->
        </body>

        <!-- Whisker assembly: base with attached moving parts -->
        <body name="whisker_base" pos="-0.1 0.1 0.015" axisangle="1 0 0 90">
            <!-- Slide joints for x and y movement -->
            <joint name="body_x_w" type="slide" axis="0 0 1" stiffness="0" armature="0.1"/>
            <joint name="body_y_w" type="slide" axis="1 0 0" stiffness="0" armature="0.1"/>
            <!-- Hinge joint for rotation -->
            <joint name="body_yaw_w" type="hinge" axis="0 1 0" armature="0.01"/>
            <!-- Cylinder geom representing the physical base (collision disabled to avoid unwanted vibrations) -->
            <geom type="cylinder" size="0.005 0.005" rgba=".8 .3 .1 .5" mass="0.1" contype="0" conaffinity="0"/>
            <!-- Cameras attached to the whisker base -->
            <camera name="whisker_cam" pos="0 0.25 0.05" xyaxes="1 0 0 0 0 -1"/>
            <camera name="whisker_cam_2" pos="-0.15 0 0.05" xyaxes="0 0 1 0 1 0"/>

            <!-- Whisker attached to the base -->
            <body name="whisker_body">
                <!-- Hinge joint connecting base to whisker body -->
                <joint name="wr0_yaw_s" type="hinge" axis="0 1 0" damping="0.01" stiffness="1" armature="0.00001"/>
                <!-- Thin cylinder geom for the whisker body -->
                <geom type="cylinder" size="0.000125 0.01" rgba=".8 .3 .7 1" mass="0.005" contype="0" conaffinity="0"/>
                <!-- Flexible cable representing the whisker -->
                <composite prefix="whisker" type="cable" curve="0 0 s" count="40 1 1" size="0.1 0 0" initial="none">
                    <plugin plugin="mujoco.elasticity.cable">
                        <config key="twist" value="40e9"/>
                        <config key="bend" value="100e9"/>
                        <config key="vmax" value="0.001"/>
                    </plugin>
                    <!-- Main joint for the cable composite -->
                    <joint kind="main" damping="0.0001" armature="0.00001"/>
                    <!-- Capsule geom for the cable element -->
                    <geom type="capsule" size=".000125" rgba=".8 0 0 1" condim="1" density="6450"/>
                </composite>
            </body>
        </body>
    </worldbody>

    <!-- Actuators: define how joints are controlled -->
    <actuator>
        <velocity joint="body_x_w" name="body_vx"/>
        <velocity joint="body_y_w" name="body_vy"/>
        <velocity joint="body_yaw_w" name="body_omega"/>
    </actuator>

    <!-- Sensors: collect simulation data -->
    <sensor>
        <!-- Whisker base sensors -->
        <jointpos joint="body_x_w" name="body_x_w"/>
        <jointpos joint="body_y_w" name="body_y_w"/>
        <jointpos joint="body_yaw_w" name="body_yaw_w"/>

        <!-- Whisker deflection sensor -->
        <jointpos joint="wr0_yaw_s" name="wr0_yaw_s"/>
    </sensor>

</mujoco>
